<?xml version="1.0"?>
<robot name="myrobot" xmlns:xacro="http://www.ros.org/wiki/xacro">

  <xacro:property name="cameraSize" value="0.05"/>
  <xacro:property name="cameraMass" value="0.1"/>

  <!-- Chassis -->
  <link name="chassis">
    <visual>
      <geometry>
        <box size="0.4 0.2 0.1"/>
      </geometry>
      <material name="green">
        <color rgba="0 0.9 0.2 1"/>
      </material>
    </visual>
    <collision>
      <geometry>
        <box size="0.4 0.2 0.1"/>
      </geometry>
    </collision>
    <inertial>
      <mass value="10.0"/>
      <origin xyz="0 0 0" rpy="0 0 0"/>
      <inertia ixx="0.1" ixy="0" ixz="0" iyy="0.2" iyz="0" izz="0.1"/>
    </inertial>
  </link>

  <!-- Caster -->
  <link name="caster">
    <visual>
      <geometry><sphere radius="0.05"/></geometry>
    </visual>
    <collision>
      <geometry><sphere radius="0.05"/></geometry>
    </collision>
    <inertial>
      <mass value="0.1"/>
      <inertia ixx="0.0001" ixy="0" ixz="0" iyy="0.0001" iyz="0" izz="0.0001"/>
    </inertial>
  </link>

  <joint name="joint_caster" type="fixed">
    <parent link="chassis"/>
    <child link="caster"/>
    <origin xyz="-0.15 0 -0.05" rpy="0 0 0"/>
  </joint>

  <!-- Left Wheel -->
  <link name="left_wheel">
    <visual>
      <geometry><cylinder radius="0.1" length="0.05"/></geometry>
      <material><color rgba="0.4 0.4 0.4 1"/></material>
    </visual>
    <collision>
      <geometry><cylinder radius="0.1" length="0.05"/></geometry>
    </collision>
    <inertial>
      <mass value="1.0"/>
      <inertia ixx="0.001" ixy="0" ixz="0" iyy="0.001" iyz="0" izz="0.001"/>
    </inertial>
  </link>

  <!-- Right Wheel -->
  <link name="right_wheel">
    <visual>
      <geometry><cylinder radius="0.1" length="0.05"/></geometry>
      <material><color rgba="0.4 0.4 0.4 1"/></material>
    </visual>
    <collision>
      <geometry><cylinder radius="0.1" length="0.05"/></geometry>
    </collision>
    <inertial>
      <mass value="1.0"/>
      <inertia ixx="0.001" ixy="0" ixz="0" iyy="0.001" iyz="0" izz="0.001"/>
    </inertial>
  </link>

  <!-- Wheel joints -->
  <joint name="left_wheel_hinge" type="continuous">
    <parent link="chassis"/>
    <child link="left_wheel"/>
    <origin xyz="0.1 0.15 0" rpy="0 0 0"/>
    <axis xyz="0 1 0"/>
    <joint_properties damping="1.0" friction="0.0"/>
  </joint>

  <joint name="right_wheel_hinge" type="continuous">
    <parent link="chassis"/>
    <child link="right_wheel"/>
    <origin xyz="0.1 -0.15 0" rpy="0 0 0"/>
    <axis xyz="0 1 0"/>
    <joint_properties damping="1.0" friction="0.0"/>
  </joint>

  <!-- Camera -->
  <link name="camera">
    <visual>
      <geometry><box size="${cameraSize} ${cameraSize} ${cameraSize}"/></geometry>
      <material><color rgba="1 1 1 1"/></material>
    </visual>
    <collision>
      <geometry><box size="${cameraSize} ${cameraSize} ${cameraSize}"/></geometry>
    </collision>
    <inertial>
      <mass value="${cameraMass}"/>
      <inertia ixx="1e-6" ixy="0" ixz="0" iyy="1e-6" iyz="0" izz="1e-6"/>
    </inertial>
  </link>

  <joint name="camera_joint" type="fixed">
    <parent link="chassis"/>
    <child link="camera"/>
    <origin xyz="0.2 0 0.05" rpy="0 0 0"/>
    <axis xyz="0 0 0"/>
  </joint>

</robot>

